db uses an image, skipping
Building web
#0 building with "default" instance using docker driver

#1 [internal] load build definition from Dockerfile
#1 transferring dockerfile: 809B done
#1 DONE 0.0s

#2 [internal] load metadata for docker.io/library/python:3.10-slim
#2 DONE 2.3s

#3 [internal] load .dockerignore
#3 transferring context: 135B done
#3 DONE 0.0s

#4 [1/6] FROM docker.io/library/python:3.10-slim@sha256:2ee0fb8794bf82af1b2db168ada5869b4c27d17720dd3b155b56c111fb4a38ae
#4 DONE 0.0s

#5 [2/6] WORKDIR /app
#5 CACHED

#6 [internal] load build context
#6 transferring context: 2.75kB done
#6 DONE 0.0s

#7 [3/6] COPY requirements.txt ./
#7 DONE 0.0s

#8 [4/6] RUN pip install --upgrade pip
#8 2.122 Requirement already satisfied: pip in /usr/local/lib/python3.10/site-packages (23.0.1)
#8 30.16 WARNING: Retrying (Retry(total=4, connect=None, read=None, redirect=None, status=None)) after connection broken by 'NewConnectionError('<pip._vendor.urllib3.connection.HTTPSConnection object at 0x743243e5e590>: Failed to establish a new connection: [Errno -3] Temporary failure in name resolution')': /simple/pip/
#8 58.68 WARNING: Retrying (Retry(total=3, connect=None, read=None, redirect=None, status=None)) after connection broken by 'NewConnectionError('<pip._vendor.urllib3.connection.HTTPSConnection object at 0x7432447ce4a0>: Failed to establish a new connection: [Errno -3] Temporary failure in name resolution')': /simple/pip/
#8 87.72 WARNING: Retrying (Retry(total=2, connect=None, read=None, redirect=None, status=None)) after connection broken by 'NewConnectionError('<pip._vendor.urllib3.connection.HTTPSConnection object at 0x7432447cca60>: Failed to establish a new connection: [Errno -3] Temporary failure in name resolution')': /simple/pip/
#8 117.7 WARNING: Retrying (Retry(total=1, connect=None, read=None, redirect=None, status=None)) after connection broken by 'NewConnectionError('<pip._vendor.urllib3.connection.HTTPSConnection object at 0x7432447cf2e0>: Failed to establish a new connection: [Errno -3] Temporary failure in name resolution')': /simple/pip/
#8 149.8 WARNING: Retrying (Retry(total=0, connect=None, read=None, redirect=None, status=None)) after connection broken by 'NewConnectionError('<pip._vendor.urllib3.connection.HTTPSConnection object at 0x7432447cd0c0>: Failed to establish a new connection: [Errno -3] Temporary failure in name resolution')': /simple/pip/
#8 177.9 WARNING: Running pip as the 'root' user can result in broken permissions and conflicting behaviour with the system package manager. It is recommended to use a virtual environment instead: https://pip.pypa.io/warnings/venv
#8 DONE 206.0s

#9 [5/6] RUN pip install --default-timeout=100 --no-cache-dir -r requirements.txt
#9 28.62 WARNING: Retrying (Retry(total=4, connect=None, read=None, redirect=None, status=None)) after connection broken by 'NewConnectionError('<pip._vendor.urllib3.connection.HTTPSConnection object at 0x777c7a239a20>: Failed to establish a new connection: [Errno -3] Temporary failure in name resolution')': /simple/flask/
#9 57.14 WARNING: Retrying (Retry(total=3, connect=None, read=None, redirect=None, status=None)) after connection broken by 'NewConnectionError('<pip._vendor.urllib3.connection.HTTPSConnection object at 0x777c7a238bb0>: Failed to establish a new connection: [Errno -3] Temporary failure in name resolution')': /simple/flask/
#9 86.17 WARNING: Retrying (Retry(total=2, connect=None, read=None, redirect=None, status=None)) after connection broken by 'NewConnectionError('<pip._vendor.urllib3.connection.HTTPSConnection object at 0x777c7a238a90>: Failed to establish a new connection: [Errno -3] Temporary failure in name resolution')': /simple/flask/
#9 116.2 WARNING: Retrying (Retry(total=1, connect=None, read=None, redirect=None, status=None)) after connection broken by 'NewConnectionError('<pip._vendor.urllib3.connection.HTTPSConnection object at 0x777c7a239d20>: Failed to establish a new connection: [Errno -3] Temporary failure in name resolution')': /simple/flask/
#9 148.2 WARNING: Retrying (Retry(total=0, connect=None, read=None, redirect=None, status=None)) after connection broken by 'NewConnectionError('<pip._vendor.urllib3.connection.HTTPSConnection object at 0x777c7a239ed0>: Failed to establish a new connection: [Errno -3] Temporary failure in name resolution')': /simple/flask/
#9 176.3 ERROR: Could not find a version that satisfies the requirement Flask==2.3.2 (from versions: none)
#9 176.3 ERROR: No matching distribution found for Flask==2.3.2
